Workbook

Sheet Controle
A1: BANCO DE DADOS — CONTROLE DE ENTREGA DAS LISTAS DE SQL
A2: Projeto Biblioteca Escolar · arquivo biblioteca_nome.sql · listas 1 a 5
A3: Preencha apenas as colunas das listas (fundo amarelo), escolhendo na lista suspensa: Entregue, Parcial ou Pendente. Entregue vale 1 ponto e Parcial vale 0,5. O restante é calculado.
A5: Cód. | B5: Aluno(a) | C5: Lista 1 CREATE | D5: Lista 2 INSERT | E5: Lista 3 SELECT | F5: Lista 4 UPDATE/agreg. | G5: Lista 5 JOIN | H5: Entregues (0 a 5) | I5: % concluído | J5: Situação | K5: Observação
A6: V01 | B6: ANTONIO MEDEIROS DA COSTA FILHO | D6: Entregue | H6: =COUNTIF(C6:G6,"Entregue")+COUNTIF(C6:G6,"Parcial")*0.5 -> 1 | I6: =H6/5 -> 0.2 | J6: =IF(COUNTA(C6:G6)=0,"Sem lançamento",IF(H6=5,"Completo",IF(H6=0,"Nada entregue","Em andamento"))) -> Em andamento
A7: V02 | B7: BIANCA DE LIMA SABOIA | D7: Entregue | H7: =COUNTIF(C7:G7,"Entregue")+COUNTIF(C7:G7,"Parcial")*0.5 -> 1 | I7: =H7/5 -> 0.2 | J7: =IF(COUNTA(C7:G7)=0,"Sem lançamento",IF(H7=5,"Completo",IF(H7=0,"Nada entregue","Em andamento"))) -> Em andamento
A8: V03 | B8: BRENO LIMA DA SILVA | D8: Entregue | E8: Parcial | H8: =COUNTIF(C8:G8,"Entregue")+COUNTIF(C8:G8,"Parcial")*0.5 -> 1.5 | I8: =H8/5 -> 0.3 | J8: =IF(COUNTA(C8:G8)=0,"Sem lançamento",IF(H8=5,"Completo",IF(H8=0,"Nada entregue","Em andamento"))) -> Em andamento
A9: V04 | B9: CECILLYA LIMA CAVALCANTE | D9: Entregue | H9: =COUNTIF(C9:G9,"Entregue")+COUNTIF(C9:G9,"Parcial")*0.5 -> 1 | I9: =H9/5 -> 0.2 | J9: =IF(COUNTA(C9:G9)=0,"Sem lançamento",IF(H9=5,"Completo",IF(H9=0,"Nada entregue","Em andamento"))) -> Em andamento
A10: V05 | B10: DAVI FALCAO DA SILVA | H10: =COUNTIF(C10:G10,"Entregue")+COUNTIF(C10:G10,"Parcial")*0.5 -> 0 | I10: =H10/5 -> 0 | J10: =IF(COUNTA(C10:G10)=0,"Sem lançamento",IF(H10=5,"Completo",IF(H10=0,"Nada entregue","Em andamento"))) -> Sem lançamento
A11: V06 | B11: DION VITOR MOREIRA DE LIMA | D11: Entregue | H11: =COUNTIF(C11:G11,"Entregue")+COUNTIF(C11:G11,"Parcial")*0.5 -> 1 | I11: =H11/5 -> 0.2 | J11: =IF(COUNTA(C11:G11)=0,"Sem lançamento",IF(H11=5,"Completo",IF(H11=0,"Nada entregue","Em andamento"))) -> Em andamento
A12: V07 | B12: EMANUEL CANDIDO RABELO OLIVEIRA | D12: Entregue | H12: =COUNTIF(C12:G12,"Entregue")+COUNTIF(C12:G12,"Parcial")*0.5 -> 1 | I12: =H12/5 -> 0.2 | J12: =IF(COUNTA(C12:G12)=0,"Sem lançamento",IF(H12=5,"Completo",IF(H12=0,"Nada entregue","Em andamento"))) -> Em andamento
A13: V08 | B13: EMILLY DOS SANTOS DA SILVA | D13: Entregue | H13: =COUNTIF(C13:G13,"Entregue")+COUNTIF(C13:G13,"Parcial")*0.5 -> 1 | I13: =H13/5 -> 0.2 | J13: =IF(COUNTA(C13:G13)=0,"Sem lançamento",IF(H13=5,"Completo",IF(H13=0,"Nada entregue","Em andamento"))) -> Em andamento
A14: V09 | B14: EMILLY RAIKA PEREIRA DE SOUSA | D14: Entregue | H14: =COUNTIF(C14:G14,"Entregue")+COUNTIF(C14:G14,"Parcial")*0.5 -> 1 | I14: =H14/5 -> 0.2 | J14: =IF(COUNTA(C14:G14)=0,"Sem lançamento",IF(H14=5,"Completo",IF(H14=0,"Nada entregue","Em andamento"))) -> Em andamento
A15: V10 | B15: ERIKA BENTO DO NASCIMENTO | D15: Entregue | H15: =COUNTIF(C15:G15,"Entregue")+COUNTIF(C15:G15,"Parcial")*0.5 -> 1 | I15: =H15/5 -> 0.2 | J15: =IF(COUNTA(C15:G15)=0,"Sem lançamento",IF(H15=5,"Completo",IF(H15=0,"Nada entregue","Em andamento"))) -> Em andamento
A16: V11 | B16: FELIPE GABRIEL BRITO LOPES | D16: Pendente | H16: =COUNTIF(C16:G16,"Entregue")+COUNTIF(C16:G16,"Parcial")*0.5 -> 0 | I16: =H16/5 -> 0 | J16: =IF(COUNTA(C16:G16)=0,"Sem lançamento",IF(H16=5,"Completo",IF(H16=0,"Nada entregue","Em andamento"))) -> Nada entregue
A17: V12 | B17: FRANCISCO GUSTAVO LIMA VIEIRA | D17: Entregue | H17: =COUNTIF(C17:G17,"Entregue")+COUNTIF(C17:G17,"Parcial")*0.5 -> 1 | I17: =H17/5 -> 0.2 | J17: =IF(COUNTA(C17:G17)=0,"Sem lançamento",IF(H17=5,"Completo",IF(H17=0,"Nada entregue","Em andamento"))) -> Em andamento
A18: V13 | B18: FRANCISCO ISMAEL DE SOUSA | D18: Entregue | H18: =COUNTIF(C18:G18,"Entregue")+COUNTIF(C18:G18,"Parcial")*0.5 -> 1 | I18: =H18/5 -> 0.2 | J18: =IF(COUNTA(C18:G18)=0,"Sem lançamento",IF(H18=5,"Completo",IF(H18=0,"Nada entregue","Em andamento"))) -> Em andamento
A19: V14 | B19: GABRIEL GIRAO DE VASCONCELOS | D19: Pendente | H19: =COUNTIF(C19:G19,"Entregue")+COUNTIF(C19:G19,"Parcial")*0.5 -> 0 | I19: =H19/5 -> 0 | J19: =IF(COUNTA(C19:G19)=0,"Sem lançamento",IF(H19=5,"Completo",IF(H19=0,"Nada entregue","Em andamento"))) -> Nada entregue
A20: V15 | B20: GABRIEL LEVY DA SIVA MIRANDA | D20: Entregue | H20: =COUNTIF(C20:G20,"Entregue")+COUNTIF(C20:G20,"Parcial")*0.5 -> 1 | I20: =H20/5 -> 0.2 | J20: =IF(COUNTA(C20:G20)=0,"Sem lançamento",IF(H20=5,"Completo",IF(H20=0,"Nada entregue","Em andamento"))) -> Em andamento
A21: V16 | B21: HEMILLY LIMA SILVEIRA | D21: Entregue | H21: =COUNTIF(C21:G21,"Entregue")+COUNTIF(C21:G21,"Parcial")*0.5 -> 1 | I21: =H21/5 -> 0.2 | J21: =IF(COUNTA(C21:G21)=0,"Sem lançamento",IF(H21=5,"Completo",IF(H21=0,"Nada entregue","Em andamento"))) -> Em andamento
A22: V17 | B22: IARLEY BARBOSA DA SILVA | D22: Entregue | H22: =COUNTIF(C22:G22,"Entregue")+COUNTIF(C22:G22,"Parcial")*0.5 -> 1 | I22: =H22/5 -> 0.2 | J22: =IF(COUNTA(C22:G22)=0,"Sem lançamento",IF(H22=5,"Completo",IF(H22=0,"Nada entregue","Em andamento"))) -> Em andamento
... A28: V23 | B28: JOSE MARIO ALMEIDA MACHADO | D28: Entregue | H28: =COUNTIF(C28:G28,"Entregue")+COUNTIF(C28:G28,"Parcial")*0.5 -> 1 | I28: =H28/5 -> 0.2 | J28: =IF(COUNTA(C28:G28)=0,"Sem lançamento",IF(H28=5,"Completo",IF(H28=0,"Nada entregue","Em andamento"))) -> Em andamento
A29: V24 | B29: JOSE MATEUS DAVID MOTA | H29: =COUNTIF(C29:G29,"Entregue")+COUNTIF(C29:G29,"Parcial")*0.5 -> 0 | I29: =H29/5 -> 0 | J29: =IF(COUNTA(C29:G29)=0,"Sem lançamento",IF(H29=5,"Completo",IF(H29=0,"Nada entregue","Em andamento"))) -> Sem lançamento
A30: V25 | B30: KARLOS ROBERTO GOMES DA SILVA PATRICIO | D30: Entregue | H30: =COUNTIF(C30:G30,"Entregue")+COUNTIF(C30:G30,"Parcial")*0.5 -> 1 | I30: =H30/5 -> 0.2 | J30: =IF(COUNTA(C30:G30)=0,"Sem lançamento",IF(H30=5,"Completo",IF(H30=0,"Nada entregue","Em andamento"))) -> Em andamento
A31: V26 | B31: KEYRISSON GABRIEL NOGUEIRA SANTIAGO | D31: Pendente | H31: =COUNTIF(C31:G31,"Entregue")+COUNTIF(C31:G31,"Parcial")*0.5 -> 0 | I31: =H31/5 -> 0 | J31: =IF(COUNTA(C31:G31)=0,"Sem lançamento",IF(H31=5,"Completo",IF(H31=0,"Nada entregue","Em andamento"))) -> Nada entregue
A32: V27 | B32: LETICIA PEREIRA DA SILVA | D32: Entregue | H32: =COUNTIF(C32:G32,"Entregue")+COUNTIF(C32:G32,"Parcial")*0.5 -> 1 | I32: =H32/5 -> 0.2 | J32: =IF(COUNTA(C32:G32)=0,"Sem lançamento",IF(H32=5,"Completo",IF(H32=0,"Nada entregue","Em andamento"))) -> Em andamento
A33: V28 | B33: LEVI GOMES DA SILVA | D33: Entregue | H33: =COUNTIF(C33:G33,"Entregue")+COUNTIF(C33:G33,"Parcial")*0.5 -> 1 | I33: =H33/5 -> 0.2 | J33: =IF(COUNTA(C33:G33)=0,"Sem lançamento",IF(H33=5,"Completo",IF(H33=0,"Nada entregue","Em andamento"))) -> Em andamento
A34: V29 | B34: MARCIO GUILHERME ARAUJO GOMES | D34: Entregue | H34: =COUNTIF(C34:G34,"Entregue")+COUNTIF(C34:G34,"Parcial")*0.5 -> 1 | I34: =H34/5 -> 0.2 | J34: =IF(COUNTA(C34:G34)=0,"Sem lançamento",IF(H34=5,"Completo",IF(H34=0,"Nada entregue","Em andamento"))) -> Em andamento
A35: V30 | B35: MARCUS VINICIUS JUCA ALMEIDA | D35: Pendente | H35: =COUNTIF(C35:G35,"Entregue")+COUNTIF(C35:G35,"Parcial")*0.5 -> 0 | I35: =H35/5 -> 0 | J35: =IF(COUNTA(C35:G35)=0,"Sem lançamento",IF(H35=5,"Completo",IF(H35=0,"Nada entregue","Em andamento"))) -> Nada entregue
A36: V31 | B36: MARIA ELIZA RIBEIRO DA SILVA | D36: Entregue | H36: =COUNTIF(C36:G36,"Entregue")+COUNTIF(C36:G36,"Parcial")*0.5 -> 1 | I36: =H36/5 -> 0.2 | J36: =IF(COUNTA(C36:G36)=0,"Sem lançamento",IF(H36=5,"Completo",IF(H36=0,"Nada entregue","Em andamento"))) -> Em andamento
A37: V32 | B37: MARIA LETICIA PEREIRA DA SILVA | D37: Entregue | H37: =COUNTIF(C37:G37,"Entregue")+COUNTIF(C37:G37,"Parcial")*0.5 -> 1 | I37: =H37/5 -> 0.2 | J37: =IF(COUNTA(C37:G37)=0,"Sem lançamento",IF(H37=5,"Completo",IF(H37=0,"Nada entregue","Em andamento"))) -> Em andamento
A38: V33 | B38: MATHEUS DA SILVA OLIVEIRA | D38: Entregue | H38: =COUNTIF(C38:G38,"Entregue")+COUNTIF(C38:G38,"Parcial")*0.5 -> 1 | I38: =H38/5 -> 0.2 | J38: =IF(COUNTA(C38:G38)=0,"Sem lançamento",IF(H38=5,"Completo",IF(H38=0,"Nada entregue","Em andamento"))) -> Em andamento
A39: V34 | B39: MATHEUS HAMILTON DA SILVA DE CASTRO | D39: Entregue | H39: =COUNTIF(C39:G39,"Entregue")+COUNTIF(C39:G39,"Parcial")*0.5 -> 1 | I39: =H39/5 -> 0.2 | J39: =IF(COUNTA(C39:G39)=0,"Sem lançamento",IF(H39=5,"Completo",IF(H39=0,"Nada entregue","Em andamento"))) -> Em andamento
A40: V35 | B40: MIGUEL ANGELO OLIVEIRA SILVA | D40: Entregue | H40: =COUNTIF(C40:G40,"Entregue")+COUNTIF(C40:G40,"Parcial")*0.5 -> 1 | I40: =H40/5 -> 0.2 | J40: =IF(COUNTA(C40:G40)=0,"Sem lançamento",IF(H40=5,"Completo",IF(H40=0,"Nada entregue","Em andamento"))) -> Em andamento
A41: V36 | B41: PAULO THIAGO MENEZES GOMES | H41: =COUNTIF(C41:G41,"Entregue")+COUNTIF(C41:G41,"Parcial")*0.5 -> 0 | I41: =H41/5 -> 0 | J41: =IF(COUNTA(C41:G41)=0,"Sem lançamento",IF(H41=5,"Completo",IF(H41=0,"Nada entregue","Em andamento"))) -> Sem lançamento
A42: V37 | B42: PEDRO YARLEI PEREIRA COSTA | D42: Entregue | H42: =COUNTIF(C42:G42,"Entregue")+COUNTIF(C42:G42,"Parcial")*0.5 -> 1 | I42: =H42/5 -> 0.2 | J42: =IF(COUNTA(C42:G42)=0,"Sem lançamento",IF(H42=5,"Completo",IF(H42=0,"Nada entregue","Em andamento"))) -> Em andamento
A43: V38 | B43: QUESIA DANTAS DOS REIS | D43: Entregue | H43: =COUNTIF(C43:G43,"Entregue")+COUNTIF(C43:G43,"Parcial")*0.5 -> 1 | I43: =H43/5 -> 0.2 | J43: =IF(COUNTA(C43:G43)=0,"Sem lançamento",IF(H43=5,"Completo",IF(H43=0,"Nada entregue","Em andamento"))) -> Em andamento
A44: V39 | B44: RAMIRO RODRIGUES RIBEIRO | D44: Parcial | H44: =COUNTIF(C44:G44,"Entregue")+COUNTIF(C44:G44,"Parcial")*0.5 -> 0.5 | I44: =H44/5 -> 0.1 | J44: =IF(COUNTA(C44:G44)=0,"Sem lançamento",IF(H44=5,"Completo",IF(H44=0,"Nada entregue","Em andamento"))) -> Em andamento
A45: V40 | B45: RUAN DEVID QUEIROZ DA SILVA | D45: Entregue | H45: =COUNTIF(C45:G45,"Entregue")+COUNTIF(C45:G45,"Parcial")*0.5 -> 1 | I45: =H45/5 -> 0.2 | J45: =IF(COUNTA(C45:G45)=0,"Sem lançamento",IF(H45=5,"Completo",IF(H45=0,"Nada entregue","Em andamento"))) -> Em andamento
A46: V41 | B46: RUAN QUEIROZ DA SILVA | D46: Entregue | H46: =COUNTIF(C46:G46,"Entregue")+COUNTIF(C46:G46,"Parcial")*0.5 -> 1 | I46: =H46/5 -> 0.2 | J46: =IF(COUNTA(C46:G46)=0,"Sem lançamento",IF(H46=5,"Completo",IF(H46=0,"Nada entregue","Em andamento"))) -> Em andamento
...

Sheet Painel
A1: PAINEL POR LISTA — ONDE A TURMA ESTÁ
A2: Atualiza sozinho conforme você preenche a aba Controle
A4: Lista | B4: Conteúdo | C4: Entregue | D4: Parcial | E4: Pendente | F4: % entregue
A5: Lista 1 | B5: Criar banco e tabelas (DDL) | C5: =COUNTIF(Controle!C6:C51,"Entregue") -> 0 | D5: =COUNTIF(Controle!C6:C51,"Parcial") -> 0 | E5: =COUNTIF(Controle!C6:C51,"Pendente") -> 0 | F5: =C5/COUNTA(Controle!B6:B51) -> 0
A6: Lista 2 | B6: Popular com os dados (INSERT) | C6: =COUNTIF(Controle!D6:D51,"Entregue") -> 36 | D6: =COUNTIF(Controle!D6:D51,"Parcial") -> 1 | E6: =COUNTIF(Controle!D6:D51,"Pendente") -> 6 | F6: =C6/COUNTA(Controle!B6:B51) -> 0.7826087
A7: Lista 3 | B7: Consultas com SELECT | C7: =COUNTIF(Controle!E6:E51,"Entregue") -> 0 | D7: =COUNTIF(Controle!E6:E51,"Parcial") -> 1 | E7: =COUNTIF(Controle!E6:E51,"Pendente") -> 0 | F7: =C7/COUNTA(Controle!B6:B51) -> 0
A8: Lista 4 | B8: UPDATE, DELETE e agregação | C8: =COUNTIF(Controle!F6:F51,"Entregue") -> 0 | D8: =COUNTIF(Controle!F6:F51,"Parcial") -> 0 | E8: =COUNTIF(Controle!F6:F51,"Pendente") -> 0 | F8: =C8/COUNTA(Controle!B6:B51) -> 0
A9: Lista 5 | B9: JOIN entre tabelas | C9: =COUNTIF(Controle!G6:G51,"Entregue") -> 0 | D9: =COUNTIF(Controle!G6:G51,"Parcial") -> 0 | E9: =COUNTIF(Controle!G6:G51,"Pendente") -> 0 | F9: =C9/COUNTA(Controle!B6:B51) -> 0
A11: Como ler este painel
A12: A coluna % entregue mostra a proporção da turma que concluiu cada lista. Como as listas são encadeadas, a primeira linha com percentual baixo indica onde a turma travou: é nela que vale retomar o conteúdo antes de seguir.
